Workbook

Sheet BOM
A1: ProjectCleanbot — Bill of Materials
A2: Hack Club Forge · A-tier · Prices in MYR · Last updated 9 Oct 2026
A4: USD → MYR rate | B4: 4.1 | G4: Total | H4: =SUM(H9:H49) -> 623.8 | I4: Used of cap | J4: =H4/B5 -> 0.76073171
A5: Forge Tier 2 | B5: 820 | G5: Remaining | H5: =B5-H4 -> 196.2 | I5: Lines to confirm | J5: =COUNTIF(J9:J49,"<>") -> 6
A6: Blue = typed input · Yellow = still needs a real price, link or fix (see 'To do' column) · Black = formula
A8: Category | B8: Product Name | C8: Source | D8: Link | E8: Qty | F8: Unit (USD) | G8: Unit (MYR) | H8: Subtotal (MYR) | I8: Notes | J8: To do
A9: Microcontroller | B9: ESP32-S3 DevKitC (N16R8) | C9: Shopee | D9: https://shopee.com.my/DIYMORE-ESP32-S3-DevKitC-1-N16R8-Development-Board-WiFi-BLE-5.0-Module-with-16MB-Flash-8MB-PSRAM-Dual-Core-240MHz-for-AIoT-Smart-Home-i.145270449.45661739634?extraParams=%7B%22display_model_id%22%3A386017578852%2C%22model_selection_l | E9: 1 | G9: 67 | H9: =E9*G9 -> 67 | I9: Microcontroller
A10: Motors & Drivers | B10: DFRobot Micro Metal Gearmotor 210:1 w/ Encoder (cable included) | C10: DFRobot | D10: https://www.dfrobot.com/product-1435.html | E10: 2 | F10: 11.5 | G10: =F10*$B$4 -> 47.15 | H10: =E10*G10 -> 94.3 | I10: Drive wheels. Check pinout + 3.3V encoder support on the DFRobot wiki.
A11: Motors & Drivers | B11: 3V 1350RPM DC Micro Metal Gearmotor (MO-3V-1350) | C11: Cytron | D11: https://my.cytron.io/p-3v-1350rpm-dc-micro-metal-gearmotor | E11: 1 | G11: 15 | H11: =E11*G11 -> 15 | I11: Brush motor. Run at 25–30% PWM with a hard duty cap in code.
A12: Motors & Drivers | B12: Micro Metal Gearmotor Bracket Pair | C12: Cytron | D12: https://my.cytron.io/p-spg10-n20-dc-geared-motor-bracket-kit | E12: 1 | G12: 8 | H12: =E12*G12 -> 8 | I12: Mounts the drive motors.
A13: Motors & Drivers | B13: L298N Motor Driver | C13: Shopee | D13: https://my.cytron.io/p-2amp-7v-30v-l298n-motor-driver-stepper-driver-2-channels | E13: 1 | G13: 5 | H13: =E13*G13 -> 5 | I13: Drives both wheel motors.
A14: Motors & Drivers | B14: IRF520 MOSFET Driver Module | C14: Shopee | D14: https://shopee.com.my/MOSFET-Button-IRF520-MOSFET-Driver-Module-for-Raspberry-pi-Arduino-ElectricA--i.96013540.5653412121?extraParams=%7B%22display_model_id%22%3A21974599353%2C%22model_selection_logic%22%3A3%7D | E14: 2 | G14: 6 | H14: =E14*G14 -> 12 | I14: One for blower, one for brush.
A15: Motors & Drivers | B15: Delta BFB1012EH Blower Fan (12V) | C15: AliExpress | D15: https://www.aliexpress.com/item/32264652512.html | E15: 1 | G15: 60 | H15: =E15*G15 -> 60 | I15: Motor for vacuuming
A16: Sensors & Input | B16: Sharp GP2D120 IR Distance Sensor (4–30cm) | C16: Cytron | D16: https://my.cytron.io/p-sharp-analog-distance-sensor-4-30cm | E16: 2 | G16: 35 | H16: =E16*G16 -> 70 | I16: Sensor for bot to slow down when getting close to walls
A17: Sensors & Input | B17: KW11 Roller Lever Microswitch (Type D) | C17: Shopee (Techmakers) | D17: https://shopee.com.my/3-Pin-KW11-5A-Small-Touch-Long-Straight-Micro-Switch-Travel-Miniature-KW12-KW-125VAC-250VAC-Contact-Limit-Lever-Switch-i.55645224.1844550241?extraParams=%7B%22display_model_id%22%3A68229909526%2C%22model_selection_logic%22%3A3%7D | E17: 2 | G17: 2.5 | H17: =E17*G17 -> 5 | I17: Bump switches.
A18: Sensors & Input | B18: On/Off Switch (SPST) | C18: Shopee | D18: https://shopee.com.my/search?keyword=on%20off%20switch | E18: 1 | G18: 3 | H18: =E18*G18 -> 3 | I18: Main power switch. | J18: Link is a search page — swap for the exact product link.
A19: Power | B19: 12V 9800mAh Polymer Li-ion Battery Pack (with BMS) | C19: Shopee | D19: https://shopee.com.my/12v-DC-Rechargeable-Battery-Polymer-Lithium-Ion-Battery-with-Charger-i.39262325.2153389061?extraParams=%7B%22display_model_id%22%3A3998849337%2C%22model_selection_logic%22%3A3%7D&rModelId=3998849337&vItemId=57165012843&vModelId=33128 | E19: 1 | G19: 69 | H19: =E19*G19 -> 69 | I19: Main battery supply
A20: Power | B20: DC5521 Female-to-Bare-Wire Cable | C20: Shopee | D20: https://shopee.com.my/12v-Female-Cable-Pure-Copper-Core-Plug-Red-Black-Power-Cord-Monitoring-Power-Male-Female-Connector-DC5521-Power-Cord-i.689628071.10587867794?extraParams=%7B%22display_model_id%22%3A86968037147%2C%22model_selection_logic%22%3A3%7D | E20: 1 | G20: 5 | H20: =E20*G20 -> 5 | I20: Mates with the battery's male output plug.
A21: Power | B21: LM2596 Buck Converter (5V fixed) | C21: Shopee | D21: https://shopee.com.my/DC-DC-buck-converter-(LM2596-step-down-fixed-output-DC-voltage)-i.35780982.55303850475?extraParams=%7B%22display_model_id%22%3A302294481058%2C%22model_selection_logic%22%3A3%7D | E21: 1 | G21: 4 | H21: =E21*G21 -> 4 | I21: 12V → 5V for ESP32 + Sharp sensors.
A22: Power | B22: Inline Fuse Holder (mini blade) | C22: Shopee | D22: https://shopee.com.my/Fuse-Holder-Black-12V-Mini-Blade-Water-Proof-Fuse-Holder-Mini-Waterproof-i.47907461.6050516278?extraParams=%7B%22display_model_id%22%3A446198273957%2C%22model_selection_logic%22%3A3%7D | E22: 1 | G22: 4 | H22: =E22*G22 -> 4 | I22: On battery + wire, protects against shorts.
A23: Power | B23: 5A Mini Blade Fuse | C23: Shopee | D23: https://shopee.com.my/1-5-10-PIECE-PRICE!!!ORIGINAL-PERODUA-JAPAN-PEC-MINI-PLUG-IN-BLADE-FUSE-FOR-PROTON-TOYOTA-HONDA-NISSAN-HYUNDAI-ETC-i.112477153.4554780740?extraParams=%7B%22display_model_id%22%3A113807436703%2C%22model_selection_logic%22%3A2%7D | E23: 1 | G23: 7 | H23: =E23*G23 -> 7 | I23: Goes in the fuse holder.
A24: Mechanical | B24: Mini Wheel 42×19mm, 3mm D-shaft (pair) | C24: Cytron | D24: https://my.cytron.io/p-mini-wheel-42x19-mm-1-pair | E24: 1 | G24: 8 | H24: =E24*G24 -> 8 | I24: Sold as a pair — qty 1 = 2 wheels.
A25: Mechanical | B25: W420 Steel Ball Castor (WL-BTU-W420) | C25: Cytron | D25: https://my.cytron.io/p-w420-steel-ball-universal-wheel-castor | E25: 1 | G25: 3 | H25: =E25*G25 -> 3 | I25: 20mm tall — add 1mm spacer to match 42mm wheels.
A26: Mechanical | B26: Flexible Shaft Coupler 3mm–6mm | C26: Shopee | D26: https://shopee.com.my/Aluminium-CNC-Motor-Jaw-Shaft-Coupler-Flexible-Coupling-Motor-Shaft-Coupling-3mm-4mm-5mm-6mm-8mm-10mm-i.33091591.948158578?extraParams=%7B%22display_model_id%22%3A30877687460%2C%22model_selection_logic%22%3A3%7D | E26: 1 | G26: 6.5 | H26: =E26*G26 -> 6.5 | I26: Brush motor → roller connector
A27: Mechanical | B27: Ball Bearing (6mm bore) | C27: Shopee | D27: https://shopee.com.my/Ball-Bearing-for-1mm-1.5mm-2mm-3mm-4mm-5mm-6mm-8mm-10mm-Metal-Shaft-RBT-Project-Toys-Model-i.114449913.18932166513?extraParams=%7B%22display_model_id%22%3A88108465059%2C%22model_selection_logic%22%3A3%7D | E27: 1 | G27: 4 | H27: =E27*G27 -> 4 | I27: Free end of the roller.
A28: Mechanical | B28: M3×8mm Bolts | C28: Shopee | D28: https://shopee.com.my/M3-M4-M5-M6-Screw-Pan-Head-Phillips-304-Stainless-Steel-GB818-Skru-i.243397959.20112160470?extraParams=%7B%22display_model_id%22%3A210689829549%2C%22model_selection_logic%22%3A2%7D | E28: 20 | G28: 0.1 | H28: =E28*G28 -> 2 | I28: Screw to go through chassis
A29: Mechanical | B29: M3×16mm Bolts | C29: Shopee | D29: https://shopee.com.my/M3-M4-M5-M6-Screw-Pan-Head-Phillips-304-Stainless-Steel-GB818-Skru-i.243397959.20112160470?extraParams=%7B%22display_model_id%22%3A210689829549%2C%22model_selection_logic%22%3A2%7D | E29: 20 | G29: 0.16 | H29: =E29*G29 -> 3.2 | I29: Screw for parts to chassis
A30: Mechanical | B30: M3 Heat-Set Brass Inserts (OD 4.5mm) | C30: Shopee | D30: https://shopee.com.my/M1.4-M2-M2.5-M3-M4-Embedded-Nut-Threaded-Insert-RoHS-Standard-Brass-3D-Printing-i.243397959.18176839221?extraParams=%7B%22display_model_id%22%3A98661196800%2C%22model_selection_logic%22%3A3%7D | E30: 1 | G30: 8 | H30: =E30*G30 -> 8 | I30: Brass inserts | J30: Listing is priced per piece — set qty to the number of inserts × unit price.
A31: Mechanical | B31: M3 Nuts | C31: Shopee | D31: https://shopee.com.my/Nylon-Lock-Nut-304-Stainless-Steel-Hexagon-M2-M2.5-M3-M4-M5-M6-M8-M10-M12-Hex-Lock-Nut-DIN985-i.243397959.4757954553?extraParams=%7B%22display_model_id%22%3A31434481836%2C%22model_selection_logic%22%3A2%7D | E31: 20 | G31: 0.1 | H31: =E31*G31 -> 2 | I31: For the screws to prevent scraping on chassis
A32: Mechanical | B32: Compression Springs 0.4×5×10mm (pack of 10) | C32: Shopee | D32: https://shopee.com.my/-LY-XHYH-304-Stainless-Steel-Compression-Spring-(wire-Diameter-0.4mm-*-Outer-Diameter-3mm-12mm-*-Length-5mm-50mm)-Shock-Absorber-Spring-Precision-Pressure-Spring-i.1525505012.28934394190?extraParams=%7B%22display_model_id%22%3A138313 | E32: 1 | G32: 4 | H32: =E32*G32 -> 4 | I32: Springs for bumper
A33: Mechanical | B33: Washable Vacuum Cloth Bag (cut to size) | C33: Shopee | D33: https://shopee.com.my/Big-Orange-Washable-Universal-Vacuum-Cleaner-Cloth-Dust-Bag-Vacuum-Cleaner-Bag-Reusable-i.216420158.5462054938?extraParams=%7B%22display_model_id%22%3A71759163225%2C%22model_selection_logic%22%3A3%7D | E33: 1 | G33: 7 | H33: =E33*G33 -> 7 | I33: Cut into the dust-bin filter.
A34: Chassis | B34: 3D Printing — PETG (chassis, roller core, motor box, bearing box) + TPU 95A (brush sleeve) | C34: TBC | E34: 1 | G34: 0 | H34: =E34*G34 -> 0 | I34: TBC — get a quote, then put the price here. | J34: Get a quote, then enter the price.
A35: Wiring & Misc | B35: Breadboard | C35: Shopee | D35: https://shopee.com.my/MB102-Breadboard-170-400-830-Holes-Breadboard-Donut-Board-Arduino-Prototype-Multi-Color-i.1165814930.25477002583?extraParams=%7B%22display_model_id%22%3A208072027950%2C%22model_selection_logic%22%3A3%7D | E35: 1 | G35: 4 | H35: =E35*G35 -> 4 | I35: For testing before soldering.
A36: Wiring & Misc | B36: Red/Black Twin Cable 16AWG, 6.2A (per metre) | C36: Shopee | D36: https://shopee.com.my/1-Meter-Red-Black-Twin-Cable-22AWG-20AWG-18AWG-17AWG-16AWG-14AWG-Electric-Electrical-Wire-Power-Cable-Speaker-Wire-i.268822975.28107542485?extraParams=%7B%22display_model_id%22%3A148740477335%2C%22model_selection_logic%22%3A3%7D | E36: 3 | G36: 2.4 | H36: =E36*G36 -> 7.2 | I36: Wire for battery to parts
A37: Wiring & Misc | B37: Red/Black Twin Cable 22AWG, 1.25A (per metre) | C37: Shopee | D37: https://shopee.com.my/1-Meter-Red-Black-Twin-Cable-22AWG-20AWG-18AWG-17AWG-16AWG-14AWG-Electric-Electrical-Wire-Power-Cable-Speaker-Wire-i.268822975.28107542485?extraParams=%7B%22display_model_id%22%3A148740477335%2C%22model_selection_logic%22%3A3%7D | E37: 2 | G37: 0.85 | H37: =E37*G37 -> 1.7 | I37: Wire for microcontroller to part
A38: Wiring & Misc | B38: Perfboard | C38: Shopee | D38: https://shopee.com.my/Double-Sided-Donut-Board-DIY-Robotics-Prototype-Board-PCB-Circuit-Board-i.1165814930.27521237000?extraParams=%7B%22display_model_id%22%3A252298009081%2C%22model_selection_logic%22%3A3%7D | E38: 1 | G38: 3 | H38: =E38*G38 -> 3 | I38: Board for electronics
A39: Wiring & Misc | B39: Dupont Jumper Wire Kit | C39: Shopee | D39: https://shopee.com.my/40pcs-Dupont-Wire-10cm-20cm-30cm-for-Breadboard-DIY-Experiment-Jumper-Wire-Breadboard-wire-i.1165814930.24676987244?extraParams=%7B%22display_model_id%22%3A187468506199%2C%22model_selection_logic%22%3A3%7D | E39: 1 | G39: 6 | H39: =E39*G39 -> 6 | I39: Wire for board to microelectronic | J39: Plan was 2 strips (M-F + M-M, 20cm).
A40: Wiring & Misc | B40: 100Ω Resistor | C40: Shopee | D40: https://shopee.com.my/10-pcs-of-Resistor-1-0.25W-1-10-100-1K-10K-100K-1M-ohm-1-4-0.25-Watt-Metal-Film-Resistance-Perintang-i.55645224.4011502286?extraParams=%7B%22display_model_id%22%3A11749661321%2C%22model_selection_logic%22%3A3%7D | E40: 1 | G40: 1 | H40: =E40*G40 -> 1 | I40: For the status LED.
A41: Wiring & Misc | B41: Green LED 5mm | C41: Shopee | D41: https://shopee.com.my/10-pcs-of-5mm-LED-Red-Yellow-Green-Blue-Orange-Light-Emitting-Diode-Extra-Long-Led-Normal-TechMakers-i.55645224.9676906423?extraParams=%7B%22display_model_id%22%3A66372892367%2C%22model_selection_logic%22%3A3%7D | E41: 1 | G41: 1 | H41: =E41*G41 -> 1 | I41: Led
A42: Wiring & Misc | B42: TO-220 Heatsink | C42: Shopee | D42: https://shopee.com.my/Heatsink-40x40x11-mm-Aluminium-Clear-Black-Gold-Anodized-i.6674515.812567757?extraParams=%7B%22display_model_id%22%3A321007863941%2C%22model_selection_logic%22%3A3%7D | E42: 2 | G42: 2 | H42: =E42*G42 -> 4 | I42: Est. — one per IRF520 to prevent overheat | J42: Estimate — confirm price.
...

Sheet Summary
A1: Spend by Category
A3: Category | B3: Items | C3: Subtotal (MYR) | D3: % of total
A4: Microcontroller | B4: =COUNTIF(BOM!$A$9:$A$49,A4) -> 1 | C4: =SUMIF(BOM!$A$9:$A$49,A4,BOM!$H$9:$H$49) -> 67 | D4: =C4/$C$13 -> 0.10740622
A5: Motors & Drivers | B5: =COUNTIF(BOM!$A$9:$A$49,A5) -> 6 | C5: =SUMIF(BOM!$A$9:$A$49,A5,BOM!$H$9:$H$49) -> 194.3 | D5: =C5/$C$13 -> 0.31147804
A6: Sensors & Input | B6: =COUNTIF(BOM!$A$9:$A$49,A6) -> 3 | C6: =SUMIF(BOM!$A$9:$A$49,A6,BOM!$H$9:$H$49) -> 78 | D6: =C6/$C$13 -> 0.12504008
A7: Power | B7: =COUNTIF(BOM!$A$9:$A$49,A7) -> 5 | C7: =SUMIF(BOM!$A$9:$A$49,A7,BOM!$H$9:$H$49) -> 89 | D7: =C7/$C$13 -> 0.14267393
A8: Mechanical | B8: =COUNTIF(BOM!$A$9:$A$49,A8) -> 10 | C8: =SUMIF(BOM!$A$9:$A$49,A8,BOM!$H$9:$H$49) -> 47.7 | D8: =C8/$C$13 -> 0.076466816
A9: Chassis | B9: =COUNTIF(BOM!$A$9:$A$49,A9) -> 1 | C9: =SUMIF(BOM!$A$9:$A$49,A9,BOM!$H$9:$H$49) -> 0 | D9: =C9/$C$13 -> 0
A10: Wiring & Misc | B10: =COUNTIF(BOM!$A$9:$A$49,A10) -> 13 | C10: =SUMIF(BOM!$A$9:$A$49,A10,BOM!$H$9:$H$49) -> 54.5 | D10: =C10/$C$13 -> 0.087367746
A11: Tools | B11: =COUNTIF(BOM!$A$9:$A$49,A11) -> 1 | C11: =SUMIF(BOM!$A$9:$A$49,A11,BOM!$H$9:$H$49) -> 40 | D11: =C11/$C$13 -> 0.064123116
A12: Shipping | B12: =COUNTIF(BOM!$A$9:$A$49,A12) -> 1 | C12: =SUMIF(BOM!$A$9:$A$49,A12,BOM!$H$9:$H$49) -> 53.3 | D12: =C12/$C$13 -> 0.085444053
A13: TOTAL | B13: =SUM(B4:B12) -> 41 | C13: =SUM(C4:C12) -> 623.8 | D13: =C13/C13 -> 1
A15: Forge A-tier cap | C15: =BOM!B5 -> 820
A16: Remaining under cap | C16: =C15-C13 -> 196.2
